Workbook

Sheet Журнал замеров (по Равичу)
A1: Дата | B1: Поселение | C1: Котёл | D1: Тип котла | E1: Топливо | F1: Горелка | G1: Тип управления | H1: Показатель | I1: Расход газа | J1: Температура дымовых газов | K1: Содержание CO₂ | L1: Содержание O₂ | M1: Содержание CO | N1: Содержание NOx | O1: Содержание SO₂ | P1: Фактическая тепловая мощность | Q1: Давление газа на входе | R1: Давление газа за горелкой | S1: Температура воды на входе | T1: Температура воды на выходе | U1: Расход воды на входе | V1: Расход воды на выходе | W1: Расход воды на входе | X1: Расход воды на выходе | Y1: Температура окружающей среды | Z1: Теплотворная способность топлива (природный газ) | AA1: Расчёт коэффициента избытка воздуха α | AB1: Расчёт потерь тепла с уходящими газами Q2​ | AC1: Расчёт потерь тепла от химической неполноты сгорания Q3​ | AD1: Расчёт КПД η
H2: Единицы измерения | I2: куб.м/ч | J2: °C | K2: % | L2: % | M2: ppm | N2: % или ppm | O2: % или ppm | P2: кВт или МВт | Q2: бар или Па | R2: бар или Па | S2: °C | T2: °C | U2: куб.м/ч | V2: куб.м/ч | W2: м/сек | X2: м/сек | Y2: °C | Z2: МДж/куб.м | AB2: кДж/ч | AC2: кДж/ч | AD2: %
A3: 45542 | B3: с. Старая Ладога, пр. Волховский, 12а | C3: №1 | D3: КВГМ-1,6-95 | E3: Газ | F3: R91A CIB UNIGAS BURNESS | H3: Малое горение | I3: 87 | J3: 144 | K3: 8.91 | L3: 3.97 | M3: 90 | S3: 40 | Y3: 20 | Z3: 35 | AA3: =21/(21-L3) -> 1.233118 | AB3: =((J3 - S3) / (J3 - Y3)) * (1 / AA3) * 1.88 * (K3 + L3) -> 16.469512 | AC3: =(M3 / 100) * Z3 -> 31.5 | AD3: =100 - (AB3 + AC3) -> 52.030488
H4: Большое горение | Y4: 20 | Z4: 35 | AA4: =21/(21-L4) -> 1 | AB4: =((J4 - S4) / (J4 - Y4)) * (1 / AA4) * 1.88 * (K4 + L4) -> 0 | AC4: =(M4 / 100) * Z4 -> 0 | AD4: =100 - (AB4 + AC4) -> 100
A5: 45542 | B5: с. Старая Ладога, пр. Волховский, 12а | C5: №2 | D5: КВГМ-1,6-95 | E5: Газ | F5: R91А CIB UNIGAS BURNESS | H5: Малое горение | I5: 76 | J5: 128 | K5: 9.02 | L5: 3.78 | M5: 46 | Y5: 20 | Z5: 35 | AA5: =21/(21-L5) -> 1.2195122 | AB5: =((J5 - S5) / (J5 - Y5)) * (1 / AA5) * 1.88 * (K5 + L5) -> 23.386643 | AC5: =(M5 / 100) * Z5 -> 16.1 | AD5: =100 - (AB5 + AC5) -> 60.513357
H6: Большое горение | Y6: 20 | Z6: 35 | AA6: =21/(21-L6) -> 1 | AB6: =((J6 - S6) / (J6 - Y6)) * (1 / AA6) * 1.88 * (K6 + L6) -> 0 | AC6: =(M6 / 100) * Z6 -> 0 | AD6: =100 - (AB6 + AC6) -> 100
A7: 45556 | B7: д. Кисельня, ул.Центральная, д.27а | C7: №1 | D7: КВГМ-2,5 | E7: Газ | F7: R92А CIB UNIGAS BURNESS | H7: Малое горение | I7: 81 | J7: 159 | K7: 9.59 | L7: 2.68 | M7: 60 | Y7: 20 | Z7: 35 | AA7: =21/(21-L7) -> 1.1462882 | AB7: =((J7 - S7) / (J7 - Y7)) * (1 / AA7) * 1.88 * (K7 + L7) -> 23.019236 | AC7: =(M7 / 100) * Z7 -> 21 | AD7: =100 - (AB7 + AC7) -> 55.980764
H8: Большое горение | I8: 294 | J8: 183 | K8: 9.62 | L8: 2.63 | M8: 50 | Y8: 20 | Z8: 35 | AA8: =21/(21-L8) -> 1.1431682 | AB8: =((J8 - S8) / (J8 - Y8)) * (1 / AA8) * 1.88 * (K8 + L8) -> 22.61764 | AC8: =(M8 / 100) * Z8 -> 17.5 | AD8: =100 - (AB8 + AC8) -> 59.88236
A9: 45556 | B9: д. Кисельня, ул.Центральная, д.27а | C9: №3 | D9: КВГМ-2,5 | E9: Газ | F9: R92А CIB UNIGAS BURNESS | H9: Малое горение | I9: 87 | J9: 96 | K9: 8.85 | L9: 4.1 | M9: 38 | Y9: 20 | Z9: 35 | AA9: =21/(21-L9) -> 1.2426036 | AB9: =((J9 - S9) / (J9 - Y9)) * (1 / AA9) * 1.88 * (K9 + L9) -> 24.748716 | AC9: =(M9 / 100) * Z9 -> 13.3 | AD9: =100 - (AB9 + AC9) -> 61.951284
H10: Большое горение | I10: 275 | J10: 139 | K10: 9.57 | L10: 2.73 | M10: 33 | Y10: 20 | Z10: 35 | AA10: =21/(21-L10) -> 1.1494253 | AB10: =((J10 - S10) / (J10 - Y10)) * (1 / AA10) * 1.88 * (K10 + L10) -> 23.499036 | AC10: =(M10 / 100) * Z10 -> 11.55 | AD10: =100 - (AB10 + AC10) -> 64.950964
A11: 45563 | B11: д. Бережки, ул.Придорожная д.2а | C11: №1 | D11: КВГМ-2,5 | E11: Газ | F11: R92А CIB UNIGAS BURNESS | H11: Малое горение | I11: 94 | J11: 125 | K11: 9.61 | L11: 2.65 | M11: 21 | S11: 48 | U11: 80 | Y11: 20 | Z11: 35 | AA11: =21/(21-L11) -> 1.1444142 | AB11: =((J11 - S11) / (J11 - Y11)) * (1 / AA11) * 1.88 * (K11 + L11) -> 14.769525 | AC11: =(M11 / 100) * Z11 -> 7.35 | AD11: =100 - (AB11 + AC11) -> 77.880475
H12: Большое горение | I12: 210 | J12: 150 | K12: 9.4 | L12: 2.7 | M12: 11 | S12: 48 | U12: 80 | Y12: 20 | Z12: 35 | AA12: =21/(21-L12) -> 1.147541 | AB12: =((J12 - S12) / (J12 - Y12)) * (1 / AA12) * 1.88 * (K12 + L12) -> 15.553633 | AC12: =(M12 / 100) * Z12 -> 3.85 | AD12: =100 - (AB12 + AC12) -> 80.596367
A13: 45563 | B13: д. Бережки, ул.Придорожная д.2а | C13: №2 | D13: КВГМ-2,5-95 | E13: Газ | F13: R92А CIB UNIGAS BURNESS | H13: Малое горение | I13: 113 | J13: 134 | K13: 9.61 | L13: 2.65 | M13: 10 | S13: 48 | U13: 80 | Y13: 20 | Z13: 35 | AA13: =21/(21-L13) -> 1.1444142 | AB13: =((J13 - S13) / (J13 - Y13)) * (1 / AA13) * 1.88 * (K13 + L13) -> 15.19353 | AC13: =(M13 / 100) * Z13 -> 3.5 | AD13: =100 - (AB13 + AC13) -> 81.30647
H14: Большое горение | I14: 195 | J14: 160 | K14: 9.65 | L14: 2.58 | M14: 14 | S14: 48 | U14: 80 | Y14: 20 | Z14: 35 | AA14: =21/(21-L14) -> 1.1400651 | AB14: =((J14 - S14) / (J14 - Y14)) * (1 / AA14) * 1.88 * (K14 + L14) -> 16.134096 | AC14: =(M14 / 100) * Z14 -> 4.9 | AD14: =100 - (AB14 + AC14) -> 78.965904
A15: 45570 | B15: д. Потанино, Центральная , 11А | C15: №2 | D15: КВа-2,5-95 | E15: Газ | F15: R92А CIB UNIGAS BURNESS | H15: Малое горение | I15: 98 | J15: 91 | K15: 7.37 | L15: 6.92 | M15: 38 | Y15: 20 | Z15: 35 | AA15: =21/(21-L15) -> 1.4914773 | AB15: =((J15 - S15) / (J15 - Y15)) * (1 / AA15) * 1.88 * (K15 + L15) -> 23.086414 | AC15: =(M15 / 100) * Z15 -> 13.3 | AD15: =100 - (AB15 + AC15) -> 63.613586
H16: Большое горение | I16: 259 | J16: 108 | K16: 9.83 | L16: 2.22 | M16: 60 | Y16: 20 | Z16: 35 | AA16: =21/(21-L16) -> 1.1182109 | AB16: =((J16 - S16) / (J16 - Y16)) * (1 / AA16) * 1.88 * (K16 + L16) -> 24.863501 | AC16: =(M16 / 100) * Z16 -> 21 | AD16: =100 - (AB16 + AC16) -> 54.136499
A17: 45577 | B17: д. Усадище, Центральная | C17: №1 | D17: КВГМ-2,5-95 | E17: Газ | F17: R92А CIB UNIGAS BURNESS | G17: Контроллер | H17: Малое горение | I17: 72 | J17: 60 | K17: 8.65 | L17: 4.49 | M17: 36 | N17: 41 | Q17: 0.1 | S17: 40 | T17: 48 | U17: 78.384 | V17: 77.8 | W17: 1.78 | X17: 1.74 | Y17: 20 | Z17: 35 | AA17: =21/(21-L17) -> 1.2719564 | AB17: =((J17 - S17) / (J17 - Y17)) * (1 / AA17) * 1.88 * (K17 + L17) -> 9.7107103 | AC17: =(M17 / 100) * Z17 -> 12.6 | AD17: =100 - (AB17 + AC17) -> 77.68929
H18: Большое горение | I18: 210 | J18: 131 | K18: 10.07 | L18: 1.77 | M18: 45 | N18: 40 | Q18: 0.1 | S18: 40 | T18: 60 | Y18: 20 | Z18: 35 | AA18: =21/(21-L18) -> 1.0920437 | AB18: =((J18 - S18) / (J18 - Y18)) * (1 / AA18) * 1.88 * (K18 + L18) -> 16.710443 | AC18: =(M18 / 100) * Z18 -> 15.75 | AD18: =100 - (AB18 + AC18) -> 67.539557
A19: 45577 | B19: д. Усадище, Центральная | C19: №3 | D19: КВГМ-2,5-95 | E19: Газ | F19: R92А CIB UNIGAS BURNESS | G19: Механика | H19: Малое горение | I19: 77 | J19: 61 | K19: 8.85 | L19: 4.11 | M19: 23 | N19: 42 | Q19: 0.1 | S19: 45 | T19: 54 | U19: 83.42 | V19: 79.5 | W19: 1.89 | X19: 1.79 | Y19: 20 | Z19: 35 | AA19: =21/(21-L19) -> 1.2433393 | AB19: =((J19 - S19) / (J19 - Y19)) * (1 / AA19) * 1.88 * (K19 + L19) -> 7.6473212 | AC19: =(M19 / 100) * Z19 -> 8.05 | AD19: =100 - (AB19 + AC19) -> 84.302679
H20: Большое горение | I20: 247 | J20: 142 | K20: 9.07 | L20: 3.67 | M20: 42 | N20: 40 | Q20: 0.1 | S20: 48 | T20: 75 | Y20: 20 | Z20: 35 | AA20: =21/(21-L20) -> 1.2117715 | AB20: =((J20 - S20) / (J20 - Y20)) * (1 / AA20) * 1.88 * (K20 + L20) -> 15.229112 | AC20: =(M20 / 100) * Z20 -> 14.7 | AD20: =100 - (AB20 + AC20) -> 70.070888
A21: 45591 | B21: д. Иссад, ул. Лесная, д.3 | C21: №1 | D21: КВГМ-2,5-95 | E21: Газ | F21: P92А CIB UNIGAS S.P.A. | G21: Контроллер | H21: Малое горение | I21: 67 | J21: 70 | K21: 9.67 | L21: 2.54 | N21: 52 | Q21: 0.11 | Y21: 20 | Z21: 35 | AA21: =21/(21-L21) -> 1.1375948 | AB21: =((J21 - S21) / (J21 - Y21)) * (1 / AA21) * 1.88 * (K21 + L21) -> 28.249707 | AC21: =(M21 / 100) * Z21 -> 0 | AD21: =100 - (AB21 + AC21) -> 71.750293
H22: Большое горение | I22: 257 | J22: 148 | K22: 9.07 | L22: 3.67 | M22: 94 | N22: 51 | Q22: 0.11 | Y22: 20 | Z22: 35 | AA22: =21/(21-L22) -> 1.2117715 | AB22: =((J22 - S22) / (J22 - Y22)) * (1 / AA22) * 1.88 * (K22 + L22) -> 22.853793 | AC22: =(M22 / 100) * Z22 -> 32.9 | AD22: =100 - (AB22 + AC22) -> 44.246207
A23: 45591 | B23: д. Иссад, ул. Лесная, д.3 | C23: №2 | D23: КВГМ-2,5-95 | E23: Газ | F23: P92А CIB UNIGAS S.P.A. | G23: Контроллер | H23: Малое горение | I23: 76 | J23: 54 | K23: 9.5 | L23: 2.78 | M23: 25 | N23: 46 | Q23: 0.11 | S23: 46 | T23: 56 | U23: 49 | V23: 63 | W23: 1.39 | X23: 1.11 | Y23: 20 | Z23: 35 | AA23: =21/(21-L23) -> 1.1525796 | AB23: =((J23 - S23) / (J23 - Y23)) * (1 / AA23) * 1.88 * (K23 + L23) -> 4.7129883 | AC23: =(M23 / 100) * Z23 -> 8.75 | AD23: =100 - (AB23 + AC23) -> 86.537012
H24: Большое горение | I24: 248 | J24: 83 | K24: 9.27 | L24: 3.3 | M24: 30 | N24: 54 | Q24: 0.11 | S24: 46 | T24: 63 | Y24: 20 | Z24: 35 | AA24: =21/(21-L24) -> 1.1864407 | AB24: =((J24 - S24) / (J24 - Y24)) * (1 / AA24) * 1.88 * (K24 + L24) -> 11.69791 | AC24: =(M24 / 100) * Z24 -> 10.5 | AD24: =100 - (AB24 + AC24) -> 77.80209
A25: 45619 | B25: с. Паша ул. Советская д. 192-е | C25: №3 | E25: Мазут | H25: Малое горение | J25: 320 | K25: 6 | L25: 14 | M25: 120 | V25: 150 | Y25: 20 | Z25: 35 | AA25: =21/(21-L25) -> 3 | AB25: =((J25 - S25) / (J25 - Y25)) * (1 / AA25) * 1.88 * (K25 + L25) -> 13.368889 | AC25: =(M25 / 100) * Z25 -> 42 | AD25: =100 - (AB25 + AC25) -> 44.631111
H26: Большое горение | Y26: 20 | Z26: 35 | AA26: =21/(21-L26) -> 1 | AB26: =((J26 - S26) / (J26 - Y26)) * (1 / AA26) * 1.88 * (K26 + L26) -> 0 | AC26: =(M26 / 100) * Z26 -> 0 | AD26: =100 - (AB26 + AC26) -> 100
A27: 45619 | B27: с. Паша ул. Советская 108-а | C27: №2 | E27: Мазут | H27: Малое горение | J27: 259 | K27: 8.2 | L27: 10 | M27: 96 | Y27: 20 | Z27: 35 | AA27: =21/(21-L27) -> 1.9090909 | AB27: =((J27 - S27) / (J27 - Y27)) * (1 / AA27) * 1.88 * (K27 + L27) -> 19.422471 | AC27: =(M27 / 100) * Z27 -> 33.6 | AD27: =100 - (AB27 + AC27) -> 46.977529
H28: Большое горение | Y28: 20 | Z28: 35 | AA28: =21/(21-L28) -> 1 | AB28: =((J28 - S28) / (J28 - Y28)) * (1 / AA28) * 1.88 * (K28 + L28) -> 0 | AC28: =(M28 / 100) * Z28 -> 0 | AD28: =100 - (AB28 + AC28) -> 100
A29: 45633 | B29: с. Колчаново, мкрн. Алексино | C29: №1 | D29: КВГ-2,5-95 | E29: Газ | F29: R73А CIB UNIGAS BURNES | H29: Малое горение | I29: 65 | J29: 85 | K29: 8.8 | L29: 4 | M29: 55 | U29: 76 | V29: 74.3 | Y29: 20 | Z29: 35 | AA29: =21/(21-L30) -> 1.1538462 | AB29: =((J30 -#REF!) / (J30 - Y29)) * (1 / AA29) * 1.88 * (K30 + L30) -> #REF! | AC29: =(M30 / 100) * Z29 -> 18.2 | AD29: =100 - (AB29 + AC29) -> #REF!
H30: Большое горение | I30: 253 | J30: 148 | K30: 9.4 | L30: 2.8 | M30: 52 | S30: 49 | T30: 74 | Y30: 20 | Z30: 35 | AA30: =21/(21-L29) -> 1.2352941 | AB30: =((J29 - S30) / (J29 - Y30)) * (1 / AA30) * 1.88 * (K29 + L29) -> 10.789134 | AC30: =(M29 / 100) * Z30 -> 19.25 | AD30: =100 - (AB30 + AC30) -> 69.960866
A31: 45633 | B31: с. Колчаново, мкрн. Алексино | C31: №2 | E31: Газ | H31: Малое горение | I31: 84 | Y31: 20 | Z31: 35 | AA31: =21/(21-#REF!) -> #REF! | AB31: =((#REF! -#REF!) / (#REF! - Y31)) * (1 / AA31) * 1.88 * (#REF! +#REF!) -> #REF! | AC31: =(#REF! / 100) * Z31 -> #REF! | AD31: =100 - (AB31 + AC31) -> #REF!
H32: Большое горение | I32: 238 | Y32: 20 | Z32: 35 | AA32: =21/(21-L32) -> 1 | AB32: =((J32 - S32) / (J32 - Y32)) * (1 / AA32) * 1.88 * (K32 + L32) -> 0 | AC32: =(M32 / 100) * Z32 -> 0 | AD32: =100 - (AB32 + AC32) -> 100
A33: 45633 | B33: с. Колчаново, ул. Молодежная, д.11 | C33: №1 | D33: КВГМ-2,0-95 | E33: Газ | F33: HR75A | G33: Механика | H33: Малое горение | I33: 72 | Y33: 20 | Z33: 35 | AA33: =21/(21-L33) -> 1 | AB33: =((J33 - S33) / (J33 - Y33)) * (1 / AA33) * 1.88 * (K33 + L33) -> 0 | AC33: =(M33 / 100) * Z33 -> 0 | AD33: =100 - (AB33 + AC33) -> 100
H34: Большое горение | I34: 162 | Y34: 20 | Z34: 35 | AA34: =21/(21-L34) -> 1 | AB34: =((J34 - S34) / (J34 - Y34)) * (1 / AA34) * 1.88 * (K34 + L34) -> 0 | AC34: =(M34 / 100) * Z34 -> 0 | AD34: =100 - (AB34 + AC34) -> 100
A35: 45633 | B35: с. Колчаново, ул. Молодежная, д.11 | C35: №2 | D35: КВГМ-2,5-95 | E35: Газ | F35: BLU 3000.1 PR TL | G35: Механика | H35: Малое горение | I35: 122 | Y35: 20 | Z35: 35 | AA35: =21/(21-L35) -> 1 | AB35: =((J35 - S35) / (J35 - Y35)) * (1 / AA35) * 1.88 * (K35 + L35) -> 0 | AC35: =(M35 / 100) * Z35 -> 0 | AD35: =100 - (AB35 + AC35) -> 100
H36: Большое горение | I36: 246 | Y36: 20 | Z36: 35 | AA36: =21/(21-L36) -> 1 | AB36: =((J36 - S36) / (J36 - Y36)) * (1 / AA36) * 1.88 * (K36 + L36) -> 0 | AC36: =(M36 / 100) * Z36 -> 0 | AD36: =100 - (AB36 + AC36) -> 100
A37: 45640 | B37: п. Аврово, ул. Центральная, 3А | C37: №1 | E37: Газ | H37: Малое горение | I37: 30 | Y37: 20 | Z37: 35 | AA37: =21/(21-L37) -> 1 | AB37: =((J37 - S37) / (J37 - Y37)) * (1 / AA37) * 1.88 * (K37 + L37) -> 0 | AC37: =(M37 / 100) * Z37 -> 0 | AD37: =100 - (AB37 + AC37) -> 100
H38: Большое горение | I38: 120 | Y38: 20 | Z38: 35 | AA38: =21/(21-L38) -> 1 | AB38: =((J38 - S38) / (J38 - Y38)) * (1 / AA38) * 1.88 * (K38 + L38) -> 0 | AC38: =(M38 / 100) * Z38 -> 0 | AD38: =100 - (AB38 + AC38) -> 100
A39: 45640 | B39: п. Аврово, ул. Центральная, 3А | C39: №2 | E39: Газ | G39: Механика | H39: Малое горение | Y39: 20 | Z39: 35 | AA39: =21/(21-L39) -> 1 | AB39: =((J39 - S39) / (J39 - Y39)) * (1 / AA39) * 1.88 * (K39 + L39) -> 0 | AC39: =(M39 / 100) * Z39 -> 0 | AD39: =100 - (AB39 + AC39) -> 100
H40: Большое горение | I40: 105 | Y40: 20 | Z40: 35 | AA40: =21/(21-L40) -> 1 | AB40: =((J40 - S40) / (J40 - Y40)) * (1 / AA40) * 1.88 * (K40 + L40) -> 0 | AC40: =(M40 / 100) * Z40 -> 0 | AD40: =100 - (AB40 + AC40) -> 100
...

Sheet Данные для УРК
A1: №1 | B1: ДКВР | C1: - | D1: п. Аврово, ул. Центральная, 3А | E1: R91А CIB UNIGAS | F1: Газ | G1: - | H1: Газ | I1: Наименование параметра защиты | J1: Размерность | K1: Газ | L1: Мазут | M1: Уголь | N1: Дизель | O1: Время срабатывания
A2: №2 | B2: КВГМ | C2: 0 | D2: д. Бережки, ул.Придорожная д.2а | E2: R92А CIB UNIGAS | F2: Мазут | G2: кПа | H2: 7595 | I2: ДАВЛЕНИЕ ТОПЛИВА
A3: №3 | B3: НИИСТУ | C3: 0.1 | D3: д. Вындин Остров ул.Школьная д.33 | E3: R73А CIB UNIGAS | F3: Дизель | G3: кгс/см² | H3: 7683 | I3: Понижение давления перед клапанами/горелкой | J3: бар | K3: 0.01 | L3: 0.8 | M3: - | N3: 0.5 | O3: Без выдержки
A4: №4 | B4: Универсал НШ | C4: 0.2 | D4: д. Иссад, мкр. ЛТЦ-4 | E4: HR75A CIB UNIGAS | F4: Уголь | G4: мбар | H4: 7771 | I4: Повышение давления перед горелкой | J4: бар | K4: 1 | L4: 1.5 | M4: - | N4: 1.2 | O4: Без выдержки
A5: №5 | B5: Ставан-250М | C5: 0.3 | D5: д. Иссад, ул. Лесная, д.3 | E5: BLU 3000.1 PR TL Ecoflam | G5: Мпа | H5: 7859 | I5: ВОЗДУХ/ТЯГА
A6: №6 | C6: 0.4 | D6: д. Кисельня, ул.Северная, д.6 | E6: R93А CIB UNIGAS | G6: бар | H6: 7983 | I6: Понижение давления воздуха перед горелкой | J6: бар | K6: 0.003 | L6: 0.003 | M6: - | N6: 0.002 | O6: Без выдержки
A7: №7 | C7: 0.5 | D7: д. Кисельня, ул.Центральная, д.27а | E7: P92А CIB UNIGAS | H7: 8107 | I7: Разрежения в топке | J7: Па | K7: 500 | L7: 500 | M7: 500 | N7: 500 | O7: ≤ 0,5 сек
C8: 0.6 | D8: с. Колчаново, мкрн. Алексино | E8: R25ABECO Ecoflam | H8: 8231 | I8: ТЕПЛОНОСИТЕЛЬ
C9: 0.7 | D9: с. Колчаново, ул. Молодежная, д.11 | E9: R72А CIB UNIGAS | H9: Мазут | I9: Понижение давления воды в котле | J9: бар | K9: 2 | L9: 2 | M9: 2 | N9: 2 | O9: Без выдержки
C10: 0.8 | D10: г. Новая Ладога, ул. Северная, д. 24 | E10: ЕММА-С3 ПРОМА | H10: 9568 | I10: Повышение давления воды в котле | J10: бар | K10: 7 | L10: 7 | M10: 7.5 | N10: 7 | O10: Без выдержки
C11: 0.9 | D11: г. Новая Ладога, ул. Суворова, д. 79 | E11: БЕРНАР | H11: 9623 | I11: Повышение температуры воды на выходе | J11: °C | K11: 95 | L11: 105 | M11: 115 | N11: 100 | O11: Без выдержки
C12: 1 | D12: г. Новая Ладога, ул. Луначарского, д. 4 | E12: TBML 360 ME Baltur | H12: 9678
C13: 1.1 | D13: г. Новая Ладога, ул. Суворова, д. 79 | E13: P60 CIB UNIGAS | H13: 9733 | I13: ГОРЕНИЕ/ТОПЛЕВО
C14: 1.2 | D14: с. Паша ул. Советская 108-а | E14: РГМГ-1 | H14: 9788 | I14: Погасание факела/отсутствие горения | J14: - | K14: Контроль | L14: Контроль | M14: Контроль | N14: Контроль | O14: Без выдержки
C15: 1.3 | D15: с. Паша ул. Станционная д. 9 | H15: 9843 | I15: Понижение температуры мазута | J15: °C | K15: - | L15: 80 | M15: - | N15: - | O15: ≤ 5 сек
C16: 1.4 | D16: с. Паша ул. Советская д. 192-е | H16: 9898 | I16: Понижение уровня угля в бункере | J16: % | K16: - | L16: - | M16: 20 | N16: - | O16: ≤ 15 сек
C17: 1.5 | D17: с. Паша ул. Павла Нечесанова д. 23- б | H17: Дизель | I17: ЭЛЕКТРИКА
C18: 1.6 | D18: д. Потанино, Центральная , 11А | H18: 10040 | I18: Исчезновение напряжения в цепях защиты | J18: - | K18: Контроль | L18: Контроль | M18: Контроль | N18: Контроль | O18: Без выдержки
C19: 1.7 | D19: п. Свирица, Новая Свирица, д.36А | H19: 10098 | I19: Остановка топливного конвейера (уголь) | J19: - | K19: - | L19: - | M19: Контроль | N19: - | O19: Без выдержки
C20: 1.8 | D20: п. Селиваново, Первомайская, 2Б | H20: 10156
C21: 1.9 | D21: с. Старая Ладога, пр. Волховский, 12а | H21: 10214
C22: 2 | D22: с. Старая Ладога, ул. Советская 30 | H22: 10272
C23: 2.1 | D23: д. Усадище, Центральная | H23: 10330
C24: 2.2 | D24: д. Хвалово, д.137 | H24: 10388
C25: 2.3 | D25: ст. Юги | H25: Уголь
C26: 2.4 | H26: 5789
C27: 2.5 | H27: 5991
C28: 2.6 | H28: 6193
C29: 2.7 | H29: 6395
C30: 2.8 | H30: 6597
C31: 2.9 | H31: 6799
C32: 3 | H32: 7001
C33: 3.1
C34: 3.2
C35: 3.3
C36: 3.4
C37: 3.5
C38: 3.6
C39: 3.7
C40: 3.8
...

Sheet График режимной наладки
A1: Название | B1: Адрес | C1: Котёл | D1: Мощность | E1: Примечание | G1: Топливо | I1: Дата | J1: Дата следующей наладки | K1: В новых РК
A2: Аврово | B2: п. Аврово, ул. Центральная, 3А | C2: №1 | D2: 1,1 | E2: КВ-ГМ-1,1 | F2: R72А CIB UNIGAS | G2: газ | H2: ТО+Прог | I2: 45376 | J2: =IF($G2="газ",DATE(YEAR(VALUE($I2))+3,MONTH(VALUE($I2)),DAY(VALUE($I2))),DATE(YEAR(VALUE($I2))+5,MONTH(VALUE($I2)),DAY(VALUE($I2)))) -> 46471
A3: Аврово | B3: п. Аврово, ул. Центральная, 3А | C3: №2 | D3: 1,1 | E3: КВ-ГМ-1,1 | F3: R72А CIB UNIGAS | G3: газ | H3: ТО+Прог | I3: 45375 | J3: =IF($G3="газ",DATE(YEAR(VALUE($I3))+3,MONTH(VALUE($I3)),DAY(VALUE($I3))),DATE(YEAR(VALUE($I3))+5,MONTH(VALUE($I3)),DAY(VALUE($I3)))) -> 46470
A4: Бережки | B4: д. Бережки, ул.Придорожная д.2а | C4: №1 | D4: 2,5 | E4: КВГМ 2,5-95 | F4: R92А CIB UNIGAS | G4: газ | I4: 45194 | J4: =IF($G4="газ",DATE(YEAR(VALUE($I4))+3,MONTH(VALUE($I4)),DAY(VALUE($I4))),DATE(YEAR(VALUE($I4))+5,MONTH(VALUE($I4)),DAY(VALUE($I4)))) -> 46290 | K4: 46254
A5: Бережки | B5: д. Бережки, ул.Придорожная д.2а | C5: №2 | D5: 2,5 | E5: КВГМ 2,5-95 | F5: R92А CIB UNIGAS | G5: газ | I5: 45352 | J5: =IF($G5="газ",DATE(YEAR(VALUE($I5))+3,MONTH(VALUE($I5)),DAY(VALUE($I5))),DATE(YEAR(VALUE($I5))+5,MONTH(VALUE($I5)),DAY(VALUE($I5)))) -> 46447
A6: Вындин остров | B6: д. Вындин Остров ул.Школьная д.33 | C6: №1 | D6: 2,5 | E6: КВГМ 2,5-95 | F6: TBML 360 ME Baltur | G6: газ | I6: 45613 | J6: =IF($G6="газ",DATE(YEAR(VALUE($I6))+3,MONTH(VALUE($I6)),DAY(VALUE($I6))),DATE(YEAR(VALUE($I6))+5,MONTH(VALUE($I6)),DAY(VALUE($I6)))) -> 46708
A7: Вындин остров | B7: д. Вындин Остров ул.Школьная д.33 | C7: №2 | D7: 2,5 | E7: КВГМ 2,5-95 | F7: R92А CIB UNIGAS | G7: газ | I7: 45372 | J7: =IF($G7="газ",DATE(YEAR(VALUE($I7))+3,MONTH(VALUE($I7)),DAY(VALUE($I7))),DATE(YEAR(VALUE($I7))+5,MONTH(VALUE($I7)),DAY(VALUE($I7)))) -> 46467
A8: Вындин остров | B8: д. Вындин Остров ул.Школьная д.33 | C8: №3 | D8: 2,5 | E8: КВГМ 2,5-95 | F8: R92А CIB UNIGAS | G8: газ | I8: 44966 | J8: =IF($G8="газ",DATE(YEAR(VALUE($I8))+3,MONTH(VALUE($I8)),DAY(VALUE($I8))),DATE(YEAR(VALUE($I8))+5,MONTH(VALUE($I8)),DAY(VALUE($I8)))) -> 46062 | K8: 46058
A9: Иссад ЛТЦ | B9: д. Иссад, мкр. ЛТЦ-4 | C9: №1 | D9: 0,25 | E9: Ставан-250 | G9: диз. топлево | H9: ТО, Прог | I9: 45699 | J9: =IF($G9="газ",DATE(YEAR(VALUE($I9))+3,MONTH(VALUE($I9)),DAY(VALUE($I9))),DATE(YEAR(VALUE($I9))+5,MONTH(VALUE($I9)),DAY(VALUE($I9)))) -> 47525
A10: Иссад ЛТЦ | B10: д. Иссад, мкр. ЛТЦ-4 | C10: №2 | D10: 0,25 | E10: Ставан-250 | F10: R25ABECO Ecoflam | G10: диз. топлево | H10: ТО, Прог | I10: 45699 | J10: =IF($G10="газ",DATE(YEAR(VALUE($I10))+3,MONTH(VALUE($I10)),DAY(VALUE($I10))),DATE(YEAR(VALUE($I10))+5,MONTH(VALUE($I10)),DAY(VALUE($I10)))) -> 47525
A11: Иссад | B11: д. Иссад, ул. Лесная, д.3 | C11: №1 | D11: 2,5 | E11: КВГМ 2,5-95 | F11: P92А CIB UNIGAS | G11: газ | H11: ТО+Прог | I11: 45737 | J11: =IF($G11="газ",DATE(YEAR(VALUE($I11))+3,MONTH(VALUE($I11)),DAY(VALUE($I11))),DATE(YEAR(VALUE($I11))+5,MONTH(VALUE($I11)),DAY(VALUE($I11)))) -> 46833
A12: Иссад | B12: д. Иссад, ул. Лесная, д.3 | C12: №2 | D12: 2,5 | E12: КВГМ 2,5-95 | F12: P92А CIB UNIGAS | G12: газ | H12: ТО+Прог | I12: 45345 | J12: =IF($G12="газ",DATE(YEAR(VALUE($I12))+3,MONTH(VALUE($I12)),DAY(VALUE($I12))),DATE(YEAR(VALUE($I12))+5,MONTH(VALUE($I12)),DAY(VALUE($I12)))) -> 46441
A13: Кисельня БМК | B13: д. Кисельня, ул.Северная, д.6 | C13: №1 | D13: 0,63 | E13: КВГМ 0,63-95 | G13: газ | I13: 44887 | J13: =IF($G13="газ",DATE(YEAR(VALUE($I13))+3,MONTH(VALUE($I13)),DAY(VALUE($I13))),DATE(YEAR(VALUE($I13))+5,MONTH(VALUE($I13)),DAY(VALUE($I13)))) -> 45983
A14: Кисельня БМК | B14: д. Кисельня, ул.Северная, д.6 | C14: №2 | D14: 0,63 | E14: КВГМ 0,63-95 | F14: P60 CIB UNIGAS | G14: газ | I14: 45525 | J14: =IF($G14="газ",DATE(YEAR(VALUE($I14))+3,MONTH(VALUE($I14)),DAY(VALUE($I14))),DATE(YEAR(VALUE($I14))+5,MONTH(VALUE($I14)),DAY(VALUE($I14)))) -> 46620
A15: Кисельня Центр | B15: д. Кисельня, ул.Центральная, д.27а | C15: №1 | D15: 2,5 | E15: КВГМ 2,5-95 | F15: R92А CIB UNIGAS | G15: газ | H15: ТО+Прог | I15: 45372 | J15: =IF($G15="газ",DATE(YEAR(VALUE($I15))+3,MONTH(VALUE($I15)),DAY(VALUE($I15))),DATE(YEAR(VALUE($I15))+5,MONTH(VALUE($I15)),DAY(VALUE($I15)))) -> 46467
A16: Кисельня Центр | B16: д. Кисельня, ул.Центральная, д.27а | C16: №2 | D16: 2,5 | E16: КВГМ 2,5-95 | F16: R92А CIB UNIGAS | G16: газ | H16: ТО+Прог | I16: 45394 | J16: =IF($G16="газ",DATE(YEAR(VALUE($I16))+3,MONTH(VALUE($I16)),DAY(VALUE($I16))),DATE(YEAR(VALUE($I16))+5,MONTH(VALUE($I16)),DAY(VALUE($I16)))) -> 46489
A17: Кисельня Центр | B17: д. Кисельня, ул.Центральная, д.27а | C17: №3 | D17: 2,5 | E17: КВГМ 2,5-95 | F17: БЕРНАР | G17: газ | I17: 45017 | J17: =IF($G17="газ",DATE(YEAR(VALUE($I17))+3,MONTH(VALUE($I17)),DAY(VALUE($I17))),DATE(YEAR(VALUE($I17))+5,MONTH(VALUE($I17)),DAY(VALUE($I17)))) -> 46113
A18: Колчаново Алексино | B18: с. Колчаново, мкрн. Алексино | C18: №1 | D18: 2,5 | E18: КВГМ 2,5-95 | F18: R73А CIB UNIGAS | G18: газ | I18: 45292 | J18: =IF($G18="газ",DATE(YEAR(VALUE($I18))+3,MONTH(VALUE($I18)),DAY(VALUE($I18))),DATE(YEAR(VALUE($I18))+5,MONTH(VALUE($I18)),DAY(VALUE($I18)))) -> 46388
A19: Колчаново Алексино | B19: с. Колчаново, мкрн. Алексино | C19: №2 | D19: 2,5 | E19: КВГМ 2,5-95 | F19: R93А CIB UNIGAS | G19: газ | H19: ТО+Прог | I19: 45716 | J19: =IF($G19="газ",DATE(YEAR(VALUE($I19))+3,MONTH(VALUE($I19)),DAY(VALUE($I19))),DATE(YEAR(VALUE($I19))+5,MONTH(VALUE($I19)),DAY(VALUE($I19)))) -> 46811
A20: Колчаново Молодежная | B20: с. Колчаново, ул. Молодежная, д.11 | C20: №1 | D20: 2,0 | E20: КВГМ 2,0-95 | F20: HR75A CIB UNIGAS | G20: газ | H20: ТО+Прог | I20: 45383 | J20: =IF($G20="газ",DATE(YEAR(VALUE($I20))+3,MONTH(VALUE($I20)),DAY(VALUE($I20))),DATE(YEAR(VALUE($I20))+5,MONTH(VALUE($I20)),DAY(VALUE($I20)))) -> 46478
A21: Колчаново Молодежная | B21: с. Колчаново, ул. Молодежная, д.11 | C21: №2 | D21: 2,5 | E21: КВГМ 2,5-95 | F21: R92А CIB UNIGAS | G21: газ | H21: ТО+Прог | I21: 45345 | J21: =IF($G21="газ",DATE(YEAR(VALUE($I21))+3,MONTH(VALUE($I21)),DAY(VALUE($I21))),DATE(YEAR(VALUE($I21))+5,MONTH(VALUE($I21)),DAY(VALUE($I21)))) -> 46441
A22: Новая Ладога Северная | B22: г. Новая Ладога, ул. Северная, д. 24 | C22: №1 | D22: 0,8 | E22: Турботерм ТТ-800 | G22: газ | I22: 44621 | J22: =IF($G22="газ",DATE(YEAR(VALUE($I22))+3,MONTH(VALUE($I22)),DAY(VALUE($I22))),DATE(YEAR(VALUE($I22))+5,MONTH(VALUE($I22)),DAY(VALUE($I22)))) -> 45717
A23: Новая Ладога Северная | B23: г. Новая Ладога, ул. Северная, д. 24 | C23: №2 | D23: 0,8 | E23: Турботерм ТТ-800 | G23: газ | I23: 44621 | J23: =IF($G23="газ",DATE(YEAR(VALUE($I23))+3,MONTH(VALUE($I23)),DAY(VALUE($I23))),DATE(YEAR(VALUE($I23))+5,MONTH(VALUE($I23)),DAY(VALUE($I23)))) -> 45717
A24: Новая Ладога Северная | B24: г. Новая Ладога, ул. Северная, д. 24 | C24: №2 | D24: 1,25 | E24: КВр-1.25-90 | G24: уголь | I24: 44621 | J24: =IF($G24="газ",DATE(YEAR(VALUE($I24))+3,MONTH(VALUE($I24)),DAY(VALUE($I24))),DATE(YEAR(VALUE($I24))+5,MONTH(VALUE($I24)),DAY(VALUE($I24)))) -> 46447
A25: Новая Ладога Северная | B25: г. Новая Ладога, ул. Северная, д. 24 | C25: №1 | D25: 1,25 | E25: КВр-1.25-90 | G25: уголь | I25: 43525 | J25: =IF($G25="газ",DATE(YEAR(VALUE($I25))+3,MONTH(VALUE($I25)),DAY(VALUE($I25))),DATE(YEAR(VALUE($I25))+5,MONTH(VALUE($I25)),DAY(VALUE($I25)))) -> 45352
A26: Новая Ладога Центральная | B26: г. Новая Ладога, ул. Суворова, д. 79 | C26: №1 | D26: 6,25 | E26: ДКВР-10/13 | G26: газ | I26: 44986 | J26: =IF($G26="газ",DATE(YEAR(VALUE($I26))+3,MONTH(VALUE($I26)),DAY(VALUE($I26))),DATE(YEAR(VALUE($I26))+5,MONTH(VALUE($I26)),DAY(VALUE($I26)))) -> 46082
A27: Новая Ладога Центральная | B27: г. Новая Ладога, ул. Суворова, д. 79 | C27: №2 | D27: 6,25 | E27: ДКВР-10/13 | G27: газ | I27: 46011 | J27: =IF($G27="газ",DATE(YEAR(VALUE($I27))+3,MONTH(VALUE($I27)),DAY(VALUE($I27))),DATE(YEAR(VALUE($I27))+5,MONTH(VALUE($I27)),DAY(VALUE($I27)))) -> 47107
A28: Новая Ладога Центральная | B28: г. Новая Ладога, ул. Суворова, д. 79 | C28: №3 | D28: 6,25 | E28: ДКВР-10/13 | G28: газ | I28: 46011 | J28: =IF($G28="газ",DATE(YEAR(VALUE($I28))+3,MONTH(VALUE($I28)),DAY(VALUE($I28))),DATE(YEAR(VALUE($I28))+5,MONTH(VALUE($I28)),DAY(VALUE($I28)))) -> 47107
A29: Новая Ладога Центральная | B29: г. Новая Ладога, ул. Суворова, д. 79 | C29: №4 | D29: 23,26 | E29: КВГМ 20-150 | G29: газ | I29: 46102 | J29: =IF($G29="газ",DATE(YEAR(VALUE($I29))+3,MONTH(VALUE($I29)),DAY(VALUE($I29))),DATE(YEAR(VALUE($I29))+5,MONTH(VALUE($I29)),DAY(VALUE($I29)))) -> 47198
A30: Новая Ладога Центральная | B30: г. Новая Ладога, ул. Суворова, д. 79 | C30: №5 | D30: 23,26 | E30: КВГМ 20-150 | G30: газ | I30: 44501 | J30: =IF($G30="газ",DATE(YEAR(VALUE($I30))+3,MONTH(VALUE($I30)),DAY(VALUE($I30))),DATE(YEAR(VALUE($I30))+5,MONTH(VALUE($I30)),DAY(VALUE($I30)))) -> 45597
A31: Новая Ладога Центральная | B31: г. Новая Ладога, ул. Суворова, д. 79 | C31: №1 | D31: 6,25 | E31: ДКВР-10/13 | G31: мазут | I31: 45717 | J31: =IF($G31="газ",DATE(YEAR(VALUE($I31))+3,MONTH(VALUE($I31)),DAY(VALUE($I31))),DATE(YEAR(VALUE($I31))+5,MONTH(VALUE($I31)),DAY(VALUE($I31)))) -> 47543
A32: Новая Ладога Центральная | B32: г. Новая Ладога, ул. Суворова, д. 79 | C32: №2 | D32: 6,25 | E32: ДКВР-10/13 | G32: мазут | I32: 46011 | J32: =IF($G32="газ",DATE(YEAR(VALUE($I32))+3,MONTH(VALUE($I32)),DAY(VALUE($I32))),DATE(YEAR(VALUE($I32))+5,MONTH(VALUE($I32)),DAY(VALUE($I32)))) -> 47837
A33: Новая Ладога Центральная | B33: г. Новая Ладога, ул. Суворова, д. 79 | C33: №2 | D33: 6,25 | E33: ДКВР-10/13 | G33: мазут | I33: 46011 | J33: =IF($G33="газ",DATE(YEAR(VALUE($I33))+3,MONTH(VALUE($I33)),DAY(VALUE($I33))),DATE(YEAR(VALUE($I33))+5,MONTH(VALUE($I33)),DAY(VALUE($I33)))) -> 47837
... A39: Новая Ладога Луначарского | B39: г. Новая Ладога, ул. Луначарского, д. 4 | C39: №2 | D39: 0,25 | E39: Турботерм 250 | G39: газ | I39: 44621 | J39: =IF($G39="газ",DATE(YEAR(VALUE($I39))+3,MONTH(VALUE($I39)),DAY(VALUE($I39))),DATE(YEAR(VALUE($I39))+5,MONTH(VALUE($I39)),DAY(VALUE($I39)))) -> 45717
A40: Паша №2 | B40: с. Паша ул. Советская 108-а | C40: №1 | D40: 1,1 | E40: КВГМ 1,1 - 95 | G40: мазут | H40: ТО, Прог | I40: 45698 | J40: =IF($G40="газ",DATE(YEAR(VALUE($I40))+3,MONTH(VALUE($I40)),DAY(VALUE($I40))),DATE(YEAR(VALUE($I40))+5,MONTH(VALUE($I40)),DAY(VALUE($I40)))) -> 47524
A41: Паша №2 | B41: с. Паша ул. Советская 108-а | C41: №2 | D41: 1,1 | E41: КВГМ 1,1 - 95 | G41: мазут | I41: 44862 | J41: =IF($G41="газ",DATE(YEAR(VALUE($I41))+3,MONTH(VALUE($I41)),DAY(VALUE($I41))),DATE(YEAR(VALUE($I41))+5,MONTH(VALUE($I41)),DAY(VALUE($I41)))) -> 46688
A42: Паша №4 Станционная | B42: с. Паша ул. Станционная д. 9 | C42: №1 | D42: 0,5 | E42: НИИСТУ-5 | G42: уголь | H42: ТО, Прог | I42: 45726 | J42: =IF($G42="газ",DATE(YEAR(VALUE($I42))+3,MONTH(VALUE($I42)),DAY(VALUE($I42))),DATE(YEAR(VALUE($I42))+5,MONTH(VALUE($I42)),DAY(VALUE($I42)))) -> 47552
A43: Паша №4 Станционная | B43: с. Паша ул. Станционная д. 9 | C43: №2 | D43: 0,5 | E43: НИИСТУ-5 | G43: уголь | H43: ТО, Прог | I43: 45698 | J43: =IF($G43="газ",DATE(YEAR(VALUE($I43))+3,MONTH(VALUE($I43)),DAY(VALUE($I43))),DATE(YEAR(VALUE($I43))+5,MONTH(VALUE($I43)),DAY(VALUE($I43)))) -> 47524
A44: Паша №1 | B44: с. Паша ул. Советская д. 192-е | C44: №1 | D44: 3 | E44: КВГМ 3,0 -95 | G44: мазут | H44: ТО, Прог | I44: 45772 | J44: =IF($G44="газ",DATE(YEAR(VALUE($I44))+3,MONTH(VALUE($I44)),DAY(VALUE($I44))),DATE(YEAR(VALUE($I44))+5,MONTH(VALUE($I44)),DAY(VALUE($I44)))) -> 47598
A45: Паша №1 | B45: с. Паша ул. Советская д. 192-е | C45: №2 | D45: 3 | E45: КВГМ 3,0 -95 | G45: мазут | H45: ТО, Прог | I45: 45756 | J45: =IF($G45="газ",DATE(YEAR(VALUE($I45))+3,MONTH(VALUE($I45)),DAY(VALUE($I45))),DATE(YEAR(VALUE($I45))+5,MONTH(VALUE($I45)),DAY(VALUE($I45)))) -> 47582
...

Sheet Универсальная РК
I1: УТВЕРЖДАЮ | O1: Нормы | P1: Примечание
I2: Зам. ген. директора - главный инженер
I3: ООО "Леноблтеплоснаб"
I4: Степанов А.В. | P4: Таблица, сравнивающая состав отходящих газов при сжигании природного газа, мазута, угля и дизельного топлива, а также соответствующие химические компоненты, их концентрации и особенности:
I5: __________________
I6: "___"_____________ 2026 г. | P6: Компонент | Q6: Природный газ | R6: Мазут | S6: Уголь | T6: Дизельное топливо
C7: РЕЖИМНАЯ КАРТА | P7: Углекислый газ (CO₂) | Q7: 8-11% | R7: 12-14% | S7: 14-18% | T7: 12-14%
B8: №№ п.п. | C8: Наименование параметров | G8: Значения | K8: Доп. откл. | P8: Окислы азота (NOₓ) | Q8: 25-500 мг/м³ | R8: 450-900 мг/м³ | S8: 300-1200 мг/м³ | T8: 200-800 мг/м³
B9: 1. | C9: ОБЩИЕ СВЕДЕНИЯ: | P9: Окись углерода (CO) | Q9: 0-150 мг/м³ | R9: 50-300 мг/м³ | S9: 100-400 мг/м³ | T9: 50-200 мг/м³
B10: 1.1. | C10: Номер котла: | G10: №1 | P10: Кислород (O₂) | Q10: 2-5% | R10: 2-5% | S10: 3-6% | T10: 3-6%
B11: 1.2. | C11: Тип котла: | G11: КВГМ | P11: Азот (N₂) | Q11: 74-78% | R11: 70-74% | S11: 70-74% | T11: 70-74%
B12: 1.3. | C12: Номинальная теплопроизводительность: | G12: 2.5 | H12: МВт | P12: Водяной пар (H₂O) | Q12: Образуется в больших количествах | R12: Образуется в меньших количествах | S12: Образуется в небольших количествах | T12: Образуется в умеренных количествах
G13: =G12/1.163 -> 2.1496131 | H13: Гкал/ч
B14: 1.4. | C14: Адрес котельной: | G14: д. Бережки, ул.Придорожная д.2а | P14: Сернистый ангидрид (SO₂) | Q14: Незначительное количество (<50 мг/м³) | R14: 600-2000 мг/м³ | S14: 500-3000 мг/м³ | T14: 50-500 мг/м³
B15: 1.5. | C15: Тип горелки: | G15: R92А CIB UNIGAS BURNESS | P15: Твердые частицы (зола, сажа) | Q15: Практически отсутствуют | R15: 50-100 мг/м³ | S15: 50-200 мг/м³ | T15: 20-100 мг/м³
B16: 1.6. | C16: Вид топлива: | G16: Газ | P16: Невыгоревшие углеводороды (CxHy) | Q16: Очень низкие концентрации | R16: Небольшие концентрации при неполном сгорании | S16: Зависит от качества сгорания | T16: Зависит от условий сгорания
B17: 2. | C17: ПАРАМЕТРЫ ТОПЛИВА И ВОЗДУХА: | P17: Точка росы, °C | Q17: 45-60°C | R17: 110-130°C | S17: 120-150°C | T17: 50-70°C
B18: 2.1. | C18: Низшая теплота сгорания топлива (Qрн): | G18: 8231 | H18: =IF(G16="Газ","ккал/м³","ккал/кг") -> ккал/м³ | K18: =IF(G16="Газ","±50","±100") -> ±50 | P18: Предел взрывоопасности | Q18: 5-15% по объёму CH₄ | R18: 0.6-6.5% по объёму | S18: 0.25-1.5% пыль угля (взвешенные частицы) | T18: 0.6-6.5% по объёму
B19: 2.2. | C19: Режим работы: | G19: Минимальный | I19: Максимальный
B20: 2.3. | C20: Давление топлива перед узлом учета (счетчиком): | I20: 275 | J20: кПа | K20: ±0.1 | P20: Нормы для оптимальной наладки газовой горелки
B21: 2.4. | C21: Давление топлива перед котлом/горелкой: | G21: 20 | H21: кПа | I21: 20 | J21: кПа | K21: ±0.1
B22: 2.5. | C22: Положение регулирующего органа топлива: | G22: 10 | H22: % | I22: 45 | J22: % | K22: ±1 | P22: Параметр | Q22: Норма для малого горения
B23: 2.6. | C23: Расход топлива (при 20°C и 760 мм рт. ст.): | G23: 94 | H23: =IF(G16="Газ","м³/ч","кг/ч") -> м³/ч | I23: 210 | J23: =IF(G16="Газ","м³/ч","кг/ч") -> м³/ч | K23: ±2 | P23: Температура дымовых газов | Q23: 140-200°C
B24: 2.7. | C24: Давление воздуха перед горелкой: | G24: 0.6 | H24: кПа | I24: 2.5 | J24: кПа | K24: ±2 | P24: Коэффициент избыточного воздуха (λ) | Q24: 1.05-1.3
B25: 2.8. | C25: Положение регулятора воздуха: | G25: 15 | H25: % | I25: 95 | J25: % | K25: ±1 | P25: Давление газа | Q25: мин: 5-10 мбар макс: 110-150 мбар
B26: 2.9. | C26: Разрежение в топке: | G26: 20 | H26: Па | I26: 115 | J26: Па | K26: ±0.2 | P26: Давление воздуха | Q26: 5-10 мбар
B27: 2.10. | C27: Температура топлива (если подогревается): | G27: - | H27: °C | I27: - | J27: °C | K27: ±2 | P27: Остаточный кислород (O₂) | Q27: 2-5%
B28: 2.11. | C28: Температура воздуха на горение: | G28: 20 | H28: °C | I28: 20 | J28: °C | K28: ±2 | P28: Окись углерода (CO) | Q28: <150 мг/м³
B29: 3. | C29: ПАРАМЕТРЫ ДЫМОВЫХ ГАЗОВ: | P29: Температура воздуха на входе | Q29: 15-25°C
B30: 3.1. | C30: Температура уходящих газов (УГ): | G30: 125 | H30: °C | I30: 155 | J30: °C | K30: ±2 | P30: Влажность воздуха | Q30: <70%
B31: 3.2. | C31: Кислород (O₂): | G31: 4 | H31: % | I31: 3 | J31: % | K31: ±0.2
B32: 3.3. | C32: =IF(G16="Мазут","Углекислый газ (RO₂):","Углекислый газ (CO₂):") -> Углекислый газ (CO₂): | G32: 9 | H32: % | I32: 9 | J32: % | K32: ±0.2 | P32: Химический состав каждого вида топлива:
B33: 3.4. | C33: =IF(G16="Мазут","Суммарные оксиды (RO₂):","Оксиды серы (SO₂):") -> Оксиды серы (SO₂): | G33: - | H33: % | I33: - | J33: % | K33: ±0.2
B34: 3.5. | C34: Окись углерода (CO): | G34: 0 | H34: ppm | I34: 0 | J34: ppm | K34: ±0.2 | P34: Топливо | Q34: Основные компоненты | R34: Дополнительные примеси
B35: 3.6. | C35: Оксиды азота (NOx): | G35: 35 | H35: ppm | I35: 150 | J35: ppm | K35: ±0.2 | P35: Природный газ | Q35: Метан (CH₄) – 70-90%, Этан (C₂H₆) – 5-15%, Пропан и бутан (C₃H₈ и C₄H₁₀) – до 5% | R35: Следы сероводорода (H₂S), азота (N₂), углекислого газа (CO₂)
B36: 3.7. | C36: Коэффициент избытка воздуха (α): | G36: 1.3 | I36: 1.1 | K36: ±0.1 | O36: >1, чем ближе, тем лучше | P36: Мазут | Q36: Углеводороды (CnHm), Сера (до 3%) | R36: Азотистые соединения, органические соединения, вода
B37: 4. | C37: ПАРАМЕТРЫ ТЕПЛОНОСИТЕЛЯ: | P37: Уголь | Q37: Углерод (C) – 50-70%, Водород (H) – 5-6%, Кислород (O) – 5-10% | R37: Сера (до 4%), зола (минеральные примеси: кремний, алюминий, железо)
B38: 4.1. | C38: Температура воды на входе в котел: | G38: 60 | H38: °C | I38: 60 | J38: °C | K38: ±2 | P38: Дизельное топливо | Q38: Углеводороды (CnHm), Сера (до 0.2% для малосернистого топлива) | R38: Азотистые соединения, следы воды и примесей
B39: 4.2. | C39: Температура воды на выходе из котла: | G39: 69 | H39: °C | I39: 80 | J39: °C | K39: ±2
B40: 4.3. | C40: Подогрев воды в котле (Δt): | G40: =G39-G38 -> 9 | H40: °C | I40: =I39-I38 -> 20 | J40: °C | K40: ±2 | O40: 10–30°C | P40: Выводы:
...

Sheet Бережки №1
I1: УТВЕРЖДАЮ | O1: Нормы | P1: Примечание
I2: Зам. ген. директора - главный инженер
I3: ООО "Леноблтеплоснаб"
I4: Степанов А.В. | P4: Таблица, сравнивающая состав отходящих газов при сжигании природного газа, мазута, угля и дизельного топлива, а также соответствующие химические компоненты, их концентрации и особенности:
I5: __________________
I6: "___"_____________ 2026 г. | P6: Компонент | Q6: Природный газ | R6: Мазут | S6: Уголь | T6: Дизельное топливо
C7: РЕЖИМНАЯ КАРТА | P7: Углекислый газ (CO₂) | Q7: 8-11% | R7: 12-14% | S7: 14-18% | T7: 12-14%
B8: №№ п.п. | C8: Наименование параметров | G8: Значения | K8: Доп. откл. | P8: Окислы азота (NOₓ) | Q8: 25-500 мг/м³ | R8: 450-900 мг/м³ | S8: 300-1200 мг/м³ | T8: 200-800 мг/м³
B9: 1. | C9: ОБЩИЕ СВЕДЕНИЯ: | P9: Окись углерода (CO) | Q9: 0-150 мг/м³ | R9: 50-300 мг/м³ | S9: 100-400 мг/м³ | T9: 50-200 мг/м³
B10: 1.1. | C10: Номер котла: | G10: №1 | P10: Кислород (O₂) | Q10: 2-5% | R10: 2-5% | S10: 3-6% | T10: 3-6%
B11: 1.2. | C11: Тип котла: | G11: КВГМ | P11: Азот (N₂) | Q11: 74-78% | R11: 70-74% | S11: 70-74% | T11: 70-74%
B12: 1.3. | C12: Номинальная теплопроизводительность: | G12: 2.5 | H12: МВт | P12: Водяной пар (H₂O) | Q12: Образуется в больших количествах | R12: Образуется в меньших количествах | S12: Образуется в небольших количествах | T12: Образуется в умеренных количествах
G13: =G12/1.163 -> 2.1496131 | H13: Гкал/ч
B14: 1.4. | C14: Адрес котельной: | G14: д. Бережки, ул.Придорожная д.2а | P14: Сернистый ангидрид (SO₂) | Q14: Незначительное количество (<50 мг/м³) | R14: 600-2000 мг/м³ | S14: 500-3000 мг/м³ | T14: 50-500 мг/м³
B15: 1.5. | C15: Тип горелки: | G15: R92А CIB UNIGAS BURNESS | P15: Твердые частицы (зола, сажа) | Q15: Практически отсутствуют | R15: 50-100 мг/м³ | S15: 50-200 мг/м³ | T15: 20-100 мг/м³
B16: 1.6. | C16: Вид топлива: | G16: Газ | P16: Невыгоревшие углеводороды (CxHy) | Q16: Очень низкие концентрации | R16: Небольшие концентрации при неполном сгорании | S16: Зависит от качества сгорания | T16: Зависит от условий сгорания
B17: 2. | C17: ПАРАМЕТРЫ ТОПЛИВА И ВОЗДУХА: | P17: Точка росы, °C | Q17: 45-60°C | R17: 110-130°C | S17: 120-150°C | T17: 50-70°C
B18: 2.1. | C18: Низшая теплота сгорания топлива (Qрн): | G18: 8231 | H18: =IF(G16="Газ","ккал/м³","ккал/кг") -> ккал/м³ | K18: =IF(G16="Газ","±50","±100") -> ±50 | P18: Предел взрывоопасности | Q18: 5-15% по объёму CH₄ | R18: 0.6-6.5% по объёму | S18: 0.25-1.5% пыль угля (взвешенные частицы) | T18: 0.6-6.5% по объёму
B19: 2.2. | C19: Режим работы: | G19: Минимальный | I19: Максимальный
B20: 2.3. | C20: Давление топлива перед узлом учета (счетчиком): | I20: 275 | J20: кПа | K20: ±0.1 | P20: Нормы для оптимальной наладки газовой горелки
B21: 2.4. | C21: Давление топлива перед котлом/горелкой: | G21: 20 | H21: кПа | I21: 20 | J21: кПа | K21: ±0.1
B22: 2.5. | C22: Положение регулирующего органа топлива: | G22: 10 | H22: % | I22: 45 | J22: % | K22: ±1 | P22: Параметр | Q22: Норма для малого горения
B23: 2.6. | C23: Расход топлива (при 20°C и 760 мм рт. ст.): | G23: 94 | H23: =IF(G16="Газ","м³/ч","кг/ч") -> м³/ч | I23: 210 | J23: =IF(G16="Газ","м³/ч","кг/ч") -> м³/ч | K23: ±2 | P23: Температура дымовых газов | Q23: 140-200°C
B24: 2.7. | C24: Давление воздуха перед горелкой: | G24: 0.6 | H24: кПа | I24: 2.5 | J24: кПа | K24: ±2 | P24: Коэффициент избыточного воздуха (λ) | Q24: 1.05-1.3
B25: 2.8. | C25: Положение регулятора воздуха: | G25: 15 | H25: % | I25: 95 | J25: % | K25: ±1 | P25: Давление газа | Q25: мин: 5-10 мбар макс: 110-150 мбар
B26: 2.9. | C26: Разрежение в топке: | G26: 20 | H26: Па | I26: 115 | J26: Па | K26: ±0.2 | P26: Давление воздуха | Q26: 5-10 мбар
B27: 2.10. | C27: Температура топлива (если подогревается): | G27: - | H27: °C | I27: - | J27: °C | K27: ±2 | P27: Остаточный кислород (O₂) | Q27: 2-5%
B28: 2.11. | C28: Температура воздуха на горение: | G28: 20 | H28: °C | I28: 20 | J28: °C | K28: ±2 | P28: Окись углерода (CO) | Q28: <150 мг/м³
B29: 3. | C29: ПАРАМЕТРЫ ДЫМОВЫХ ГАЗОВ: | P29: Температура воздуха на входе | Q29: 15-25°C
B30: 3.1. | C30: Температура уходящих газов (УГ): | G30: 125 | H30: °C | I30: 155 | J30: °C | K30: ±2 | P30: Влажность воздуха | Q30: <70%
B31: 3.2. | C31: Кислород (O₂): | G31: 4 | H31: % | I31: 3 | J31: % | K31: ±0.2
B32: 3.3. | C32: =IF(G16="Мазут","Углекислый газ (RO₂):","Углекислый газ (CO₂):") -> Углекислый газ (CO₂): | G32: 9 | H32: % | I32: 9 | J32: % | K32: ±0.2 | P32: Химический состав каждого вида топлива:
B33: 3.4. | C33: =IF(G16="Мазут","Суммарные оксиды (RO₂):","Оксиды серы (SO₂):") -> Оксиды серы (SO₂): | G33: - | H33: % | I33: - | J33: % | K33: ±0.2
B34: 3.5. | C34: Окись углерода (CO): | G34: 0 | H34: ppm | I34: 0 | J34: ppm | K34: ±0.2 | P34: Топливо | Q34: Основные компоненты | R34: Дополнительные примеси
B35: 3.6. | C35: Оксиды азота (NOx): | G35: 35 | H35: ppm | I35: 150 | J35: ppm | K35: ±0.2 | P35: Природный газ | Q35: Метан (CH₄) – 70-90%, Этан (C₂H₆) – 5-15%, Пропан и бутан (C₃H₈ и C₄H₁₀) – до 5% | R35: Следы сероводорода (H₂S), азота (N₂), углекислого газа (CO₂)
B36: 3.7. | C36: Коэффициент избытка воздуха (α): | G36: 1.3 | I36: 1.1 | K36: ±0.1 | O36: >1, чем ближе, тем лучше | P36: Мазут | Q36: Углеводороды (CnHm), Сера (до 3%) | R36: Азотистые соединения, органические соединения, вода
B37: 4. | C37: ПАРАМЕТРЫ ТЕПЛОНОСИТЕЛЯ: | P37: Уголь | Q37: Углерод (C) – 50-70%, Водород (H) – 5-6%, Кислород (O) – 5-10% | R37: Сера (до 4%), зола (минеральные примеси: кремний, алюминий, железо)
B38: 4.1. | C38: Температура воды на входе в котел: | G38: 60 | H38: °C | I38: 60 | J38: °C | K38: ±2 | P38: Дизельное топливо | Q38: Углеводороды (CnHm), Сера (до 0.2% для малосернистого топлива) | R38: Азотистые соединения, следы воды и примесей
B39: 4.2. | C39: Температура воды на выходе из котла: | G39: 69 | H39: °C | I39: 80 | J39: °C | K39: ±2
B40: 4.3. | C40: Подогрев воды в котле (Δt): | G40: =G39-G38 -> 9 | H40: °C | I40: =I39-I38 -> 20 | J40: °C | K40: ±2 | O40: 10–30°C | P40: Выводы:
...

Sheet ВындинОстров №3
I1: УТВЕРЖДАЮ | O1: Нормы | P1: Примечание
I2: Зам. ген. директора - главный инженер
I3: ООО "Леноблтеплоснаб"
I4: Степанов А.В. | P4: Таблица, сравнивающая состав отходящих газов при сжигании природного газа, мазута, угля и дизельного топлива, а также соответствующие химические компоненты, их концентрации и особенности:
I5: __________________
I6: "___"_____________ 2026 г. | P6: Компонент | Q6: Природный газ | R6: Мазут | S6: Уголь | T6: Дизельное топливо
C7: РЕЖИМНАЯ КАРТА | P7: Углекислый газ (CO₂) | Q7: 8-11% | R7: 12-14% | S7: 14-18% | T7: 12-14%
B8: №№ п.п. | C8: Наименование параметров | G8: Значения | K8: Доп. откл. | P8: Окислы азота (NOₓ) | Q8: 25-500 мг/м³ | R8: 450-900 мг/м³ | S8: 300-1200 мг/м³ | T8: 200-800 мг/м³
B9: 1. | C9: ОБЩИЕ СВЕДЕНИЯ: | P9: Окись углерода (CO) | Q9: 0-150 мг/м³ | R9: 50-300 мг/м³ | S9: 100-400 мг/м³ | T9: 50-200 мг/м³
B10: 1.1. | C10: Номер котла: | G10: №3 | P10: Кислород (O₂) | Q10: 2-5% | R10: 2-5% | S10: 3-6% | T10: 3-6%
B11: 1.2. | C11: Тип котла: | G11: КВГМ | P11: Азот (N₂) | Q11: 74-78% | R11: 70-74% | S11: 70-74% | T11: 70-74%
B12: 1.3. | C12: Номинальная теплопроизводительность: | G12: 2.5 | H12: МВт | P12: Водяной пар (H₂O) | Q12: Образуется в больших количествах | R12: Образуется в меньших количествах | S12: Образуется в небольших количествах | T12: Образуется в умеренных количествах
G13: =G12/1.163 -> 2.1496131 | H13: Гкал/ч
B14: 1.4. | C14: Адрес котельной: | G14: д. Вындин Остров ул.Школьная д.33 | P14: Сернистый ангидрид (SO₂) | Q14: Незначительное количество (<50 мг/м³) | R14: 600-2000 мг/м³ | S14: 500-3000 мг/м³ | T14: 50-500 мг/м³
B15: 1.5. | C15: Тип горелки: | G15: R92А CIB UNIGAS BURNESS | P15: Твердые частицы (зола, сажа) | Q15: Практически отсутствуют | R15: 50-100 мг/м³ | S15: 50-200 мг/м³ | T15: 20-100 мг/м³
B16: 1.6. | C16: Вид топлива: | G16: Газ | P16: Невыгоревшие углеводороды (CxHy) | Q16: Очень низкие концентрации | R16: Небольшие концентрации при неполном сгорании | S16: Зависит от качества сгорания | T16: Зависит от условий сгорания
B17: 2. | C17: ПАРАМЕТРЫ ТОПЛИВА И ВОЗДУХА: | P17: Точка росы, °C | Q17: 45-60°C | R17: 110-130°C | S17: 120-150°C | T17: 50-70°C
B18: 2.1. | C18: Низшая теплота сгорания топлива (Qрн): | G18: 8107 | H18: =IF(G16="Газ","ккал/м³","ккал/кг") -> ккал/м³ | K18: =IF(G16="Газ","±50","±100") -> ±50 | P18: Предел взрывоопасности | Q18: 5-15% по объёму CH₄ | R18: 0.6-6.5% по объёму | S18: 0.25-1.5% пыль угля (взвешенные частицы) | T18: 0.6-6.5% по объёму
B19: 2.2. | C19: Режим работы: | G19: Минимальный | I19: Максимальный
B20: 2.3. | C20: Давление топлива перед узлом учета (счетчиком): | I20: 275 | J20: кПа | K20: ±0.1 | P20: Нормы для оптимальной наладки газовой горелки
B21: 2.4. | C21: Давление топлива перед котлом/горелкой: | G21: 21 | H21: кПа | I21: 21 | J21: кПа | K21: ±0.1
B22: 2.5. | C22: Положение регулирующего органа топлива: | G22: 10 | H22: % | I22: 45 | J22: % | K22: ±1 | P22: Параметр | Q22: Норма для малого горения
B23: 2.6. | C23: Расход топлива (при 20°C и 760 мм рт. ст.): | G23: 89 | H23: =IF(G16="Газ","м³/ч","кг/ч") -> м³/ч | I23: 215 | J23: =IF(G16="Газ","м³/ч","кг/ч") -> м³/ч | K23: ±2 | P23: Температура дымовых газов | Q23: 140-200°C
B24: 2.7. | C24: Давление воздуха перед горелкой: | G24: 0.6 | H24: кПа | I24: 2.5 | J24: кПа | K24: ±2 | P24: Коэффициент избыточного воздуха (λ) | Q24: 1.05-1.3
B25: 2.8. | C25: Положение регулятора воздуха: | G25: 16 | H25: % | I25: 96 | J25: % | K25: ±1 | P25: Давление газа | Q25: мин: 5-10 мбар макс: 110-150 мбар
B26: 2.9. | C26: Разрежение в топке: | G26: 19 | H26: Па | I26: 110 | J26: Па | K26: ±0.2 | P26: Давление воздуха | Q26: 5-10 мбар
B27: 2.10. | C27: Температура топлива (если подогревается): | G27: - | H27: °C | I27: - | J27: °C | K27: ±2 | P27: Остаточный кислород (O₂) | Q27: 2-5%
B28: 2.11. | C28: Температура воздуха на горение: | G28: 20 | H28: °C | I28: 20 | J28: °C | K28: ±2 | P28: Окись углерода (CO) | Q28: <150 мг/м³
B29: 3. | C29: ПАРАМЕТРЫ ДЫМОВЫХ ГАЗОВ: | P29: Температура воздуха на входе | Q29: 15-25°C
B30: 3.1. | C30: Температура уходящих газов (УГ): | G30: 110 | H30: °C | I30: 160 | J30: °C | K30: ±2 | P30: Влажность воздуха | Q30: <70%
B31: 3.2. | C31: Кислород (O₂): | G31: 4 | H31: % | I31: 3 | J31: % | K31: ±0.2
B32: 3.3. | C32: =IF(G16="Мазут","Углекислый газ (RO₂):","Углекислый газ (CO₂):") -> Углекислый газ (CO₂): | G32: 9 | H32: % | I32: 9 | J32: % | K32: ±0.2 | P32: Химический состав каждого вида топлива:
B33: 3.4. | C33: =IF(G16="Мазут","Суммарные оксиды (RO₂):","Оксиды серы (SO₂):") -> Оксиды серы (SO₂): | G33: - | H33: % | I33: - | J33: % | K33: ±0.2
B34: 3.5. | C34: Окись углерода (CO): | G34: 0 | H34: ppm | I34: 0 | J34: ppm | K34: ±0.2 | P34: Топливо | Q34: Основные компоненты | R34: Дополнительные примеси
B35: 3.6. | C35: Оксиды азота (NOx): | G35: 35 | H35: ppm | I35: 150 | J35: ppm | K35: ±0.2 | P35: Природный газ | Q35: Метан (CH₄) – 70-90%, Этан (C₂H₆) – 5-15%, Пропан и бутан (C₃H₈ и C₄H₁₀) – до 5% | R35: Следы сероводорода (H₂S), азота (N₂), углекислого газа (CO₂)
B36: 3.7. | C36: Коэффициент избытка воздуха (α): | G36: 1.3 | I36: 1.1 | K36: ±0.1 | O36: >1, чем ближе, тем лучше | P36: Мазут | Q36: Углеводороды (CnHm), Сера (до 3%) | R36: Азотистые соединения, органические соединения, вода
B37: 4. | C37: ПАРАМЕТРЫ ТЕПЛОНОСИТЕЛЯ: | P37: Уголь | Q37: Углерод (C) – 50-70%, Водород (H) – 5-6%, Кислород (O) – 5-10% | R37: Сера (до 4%), зола (минеральные примеси: кремний, алюминий, железо)
B38: 4.1. | C38: Температура воды на входе в котел: | G38: 59 | H38: °C | I38: 59 | J38: °C | K38: ±2 | P38: Дизельное топливо | Q38: Углеводороды (CnHm), Сера (до 0.2% для малосернистого топлива) | R38: Азотистые соединения, следы воды и примесей
B39: 4.2. | C39: Температура воды на выходе из котла: | G39: 68 | H39: °C | I39: 80 | J39: °C | K39: ±2
B40: 4.3. | C40: Подогрев воды в котле (Δt): | G40: =G39-G38 -> 9 | H40: °C | I40: =I39-I38 -> 21 | J40: °C | K40: ±2 | O40: 10–30°C | P40: Выводы:
...

Sheet Кис.Север. №1
I1: УТВЕРЖДАЮ | O1: Нормы | P1: Примечание
I2: Зам. ген. директора - главный инженер
I3: ООО "Леноблтеплоснаб"
I4: Степанов А.В. | P4: Таблица, сравнивающая состав отходящих газов при сжигании природного газа, мазута, угля и дизельного топлива, а также соответствующие химические компоненты, их концентрации и особенности:
I5: __________________
I6: "___"_____________ 2026 г. | P6: Компонент | Q6: Природный газ | R6: Мазут | S6: Уголь | T6: Дизельное топливо
C7: РЕЖИМНАЯ КАРТА | P7: Углекислый газ (CO₂) | Q7: 8-11% | R7: 12-14% | S7: 14-18% | T7: 12-14%
B8: №№ п.п. | C8: Наименование параметров | G8: Значения | K8: Доп. откл. | P8: Окислы азота (NOₓ) | Q8: 25-500 мг/м³ | R8: 450-900 мг/м³ | S8: 300-1200 мг/м³ | T8: 200-800 мг/м³
B9: 1. | C9: ОБЩИЕ СВЕДЕНИЯ: | P9: Окись углерода (CO) | Q9: 0-150 мг/м³ | R9: 50-300 мг/м³ | S9: 100-400 мг/м³ | T9: 50-200 мг/м³
B10: 1.1. | C10: Номер котла: | G10: №1 | P10: Кислород (O₂) | Q10: 2-5% | R10: 2-5% | S10: 3-6% | T10: 3-6%
B11: 1.2. | C11: Тип котла: | G11: КВГМ | P11: Азот (N₂) | Q11: 74-78% | R11: 70-74% | S11: 70-74% | T11: 70-74%
B12: 1.3. | C12: Номинальная теплопроизводительность: | G12: 0.6 | H12: МВт | P12: Водяной пар (H₂O) | Q12: Образуется в больших количествах | R12: Образуется в меньших количествах | S12: Образуется в небольших количествах | T12: Образуется в умеренных количествах
G13: =G12/1.163 -> 0.51590714 | H13: Гкал/ч
B14: 1.4. | C14: Адрес котельной: | G14: д. Кисельня, ул.Северная, д.6 | P14: Сернистый ангидрид (SO₂) | Q14: Незначительное количество (<50 мг/м³) | R14: 600-2000 мг/м³ | S14: 500-3000 мг/м³ | T14: 50-500 мг/м³
B15: 1.5. | C15: Тип горелки: | G15: R73А CIB UNIGAS BURNES | P15: Твердые частицы (зола, сажа) | Q15: Практически отсутствуют | R15: 50-100 мг/м³ | S15: 50-200 мг/м³ | T15: 20-100 мг/м³
B16: 1.6. | C16: Вид топлива: | G16: Газ | P16: Невыгоревшие углеводороды (CxHy) | Q16: Очень низкие концентрации | R16: Небольшие концентрации при неполном сгорании | S16: Зависит от качества сгорания | T16: Зависит от условий сгорания
B17: 2. | C17: ПАРАМЕТРЫ ТОПЛИВА И ВОЗДУХА: | P17: Точка росы, °C | Q17: 45-60°C | R17: 110-130°C | S17: 120-150°C | T17: 50-70°C
B18: 2.1. | C18: Низшая теплота сгорания топлива (Qрн): | G18: 8231 | H18: =IF(G16="Газ","ккал/м³","ккал/кг") -> ккал/м³ | K18: =IF(G16="Газ","±50","±100") -> ±50 | P18: Предел взрывоопасности | Q18: 5-15% по объёму CH₄ | R18: 0.6-6.5% по объёму | S18: 0.25-1.5% пыль угля (взвешенные частицы) | T18: 0.6-6.5% по объёму
B19: 2.2. | C19: Режим работы: | G19: Минимальный | I19: Максимальный
B20: 2.3. | C20: Давление топлива перед узлом учета (счетчиком): | I20: 275 | J20: кПа | K20: ±0.1 | P20: Нормы для оптимальной наладки газовой горелки
B21: 2.4. | C21: Давление топлива перед котлом/горелкой: | G21: 20 | H21: кПа | I21: 20 | J21: кПа | K21: ±0.1
B22: 2.5. | C22: Положение регулирующего органа топлива: | G22: 10 | H22: % | I22: 45 | J22: % | K22: ±1 | P22: Параметр | Q22: Норма для малого горения
B23: 2.6. | C23: Расход топлива (при 20°C и 760 мм рт. ст.): | G23: 94 | H23: =IF(G16="Газ","м³/ч","кг/ч") -> м³/ч | I23: 210 | J23: =IF(G16="Газ","м³/ч","кг/ч") -> м³/ч | K23: ±2 | P23: Температура дымовых газов | Q23: 140-200°C
B24: 2.7. | C24: Давление воздуха перед горелкой: | G24: 0.6 | H24: кПа | I24: 2.5 | J24: кПа | K24: ±2 | P24: Коэффициент избыточного воздуха (λ) | Q24: 1.05-1.3
B25: 2.8. | C25: Положение регулятора воздуха: | G25: 15 | H25: % | I25: 95 | J25: % | K25: ±1 | P25: Давление газа | Q25: мин: 5-10 мбар макс: 110-150 мбар
B26: 2.9. | C26: Разрежение в топке: | G26: 20 | H26: Па | I26: 115 | J26: Па | K26: ±0.2 | P26: Давление воздуха | Q26: 5-10 мбар
B27: 2.10. | C27: Температура топлива (если подогревается): | G27: - | H27: °C | I27: - | J27: °C | K27: ±2 | P27: Остаточный кислород (O₂) | Q27: 2-5%
B28: 2.11. | C28: Температура воздуха на горение: | G28: 20 | H28: °C | I28: 20 | J28: °C | K28: ±2 | P28: Окись углерода (CO) | Q28: <150 мг/м³
B29: 3. | C29: ПАРАМЕТРЫ ДЫМОВЫХ ГАЗОВ: | P29: Температура воздуха на входе | Q29: 15-25°C
B30: 3.1. | C30: Температура уходящих газов (УГ): | G30: 125 | H30: °C | I30: 155 | J30: °C | K30: ±2 | P30: Влажность воздуха | Q30: <70%
B31: 3.2. | C31: Кислород (O₂): | G31: 4 | H31: % | I31: 3 | J31: % | K31: ±0.2
B32: 3.3. | C32: =IF(G16="Мазут","Углекислый газ (RO₂):","Углекислый газ (CO₂):") -> Углекислый газ (CO₂): | G32: 9 | H32: % | I32: 9 | J32: % | K32: ±0.2 | P32: Химический состав каждого вида топлива:
B33: 3.4. | C33: =IF(G16="Мазут","Суммарные оксиды (RO₂):","Оксиды серы (SO₂):") -> Оксиды серы (SO₂): | G33: - | H33: % | I33: - | J33: % | K33: ±0.2
B34: 3.5. | C34: Окись углерода (CO): | G34: 0 | H34: ppm | I34: 0 | J34: ppm | K34: ±0.2 | P34: Топливо | Q34: Основные компоненты | R34: Дополнительные примеси
B35: 3.6. | C35: Оксиды азота (NOx): | G35: 35 | H35: ppm | I35: 150 | J35: ppm | K35: ±0.2 | P35: Природный газ | Q35: Метан (CH₄) – 70-90%, Этан (C₂H₆) – 5-15%, Пропан и бутан (C₃H₈ и C₄H₁₀) – до 5% | R35: Следы сероводорода (H₂S), азота (N₂), углекислого газа (CO₂)
B36: 3.7. | C36: Коэффициент избытка воздуха (α): | G36: 1.3 | I36: 1.1 | K36: ±0.1 | O36: >1, чем ближе, тем лучше | P36: Мазут | Q36: Углеводороды (CnHm), Сера (до 3%) | R36: Азотистые соединения, органические соединения, вода
B37: 4. | C37: ПАРАМЕТРЫ ТЕПЛОНОСИТЕЛЯ: | P37: Уголь | Q37: Углерод (C) – 50-70%, Водород (H) – 5-6%, Кислород (O) – 5-10% | R37: Сера (до 4%), зола (минеральные примеси: кремний, алюминий, железо)
B38: 4.1. | C38: Температура воды на входе в котел: | G38: 60 | H38: °C | I38: 60 | J38: °C | K38: ±2 | P38: Дизельное топливо | Q38: Углеводороды (CnHm), Сера (до 0.2% для малосернистого топлива) | R38: Азотистые соединения, следы воды и примесей
B39: 4.2. | C39: Температура воды на выходе из котла: | G39: 69 | H39: °C | I39: 80 | J39: °C | K39: ±2
B40: 4.3. | C40: Подогрев воды в котле (Δt): | G40: =G39-G38 -> 9 | H40: °C | I40: =I39-I38 -> 20 | J40: °C | K40: ±2 | O40: 10–30°C | P40: Выводы:
...
